Workbook

Sheet Data
A1: SKU | B1: Nazwa produktu | C1: Kategoria | D1: Data | E1: Ilość wydana | F1: Wartość jednostkowa | G1: Wartość sprzedaży
A2: SKU-0001 | B2: Segregator A4 Compact | C2: Artykuły biurowe | D2: 45505 | E2: 2 | F2: 24.11 | G2: =dane_sprzedazy_sku__3[[#This Row],[Ilość wydana]]*dane_sprzedazy_sku__3[[#This Row],[Wartość jednostkowa]] -> 48.22
A3: SKU-0001 | B3: Segregator A4 Compact | C3: Artykuły biurowe | D3: 45536 | E3: 2 | F3: 23.61 | G3: =dane_sprzedazy_sku__3[[#This Row],[Ilość wydana]]*dane_sprzedazy_sku__3[[#This Row],[Wartość jednostkowa]] -> 47.22
A4: SKU-0001 | B4: Segregator A4 Compact | C4: Artykuły biurowe | D4: 45566 | E4: 2 | F4: 23.55 | G4: =dane_sprzedazy_sku__3[[#This Row],[Ilość wydana]]*dane_sprzedazy_sku__3[[#This Row],[Wartość jednostkowa]] -> 47.1
A5: SKU-0001 | B5: Segregator A4 Compact | C5: Artykuły biurowe | D5: 45597 | E5: 2 | F5: 24.07 | G5: =dane_sprzedazy_sku__3[[#This Row],[Ilość wydana]]*dane_sprzedazy_sku__3[[#This Row],[Wartość jednostkowa]] -> 48.14
A6: SKU-0001 | B6: Segregator A4 Compact | C6: Artykuły biurowe | D6: 45627 | E6: 2 | F6: 22.59 | G6: =dane_sprzedazy_sku__3[[#This Row],[Ilość wydana]]*dane_sprzedazy_sku__3[[#This Row],[Wartość jednostkowa]] -> 45.18
A7: SKU-0001 | B7: Segregator A4 Compact | C7: Artykuły biurowe | D7: 45658 | E7: 2 | F7: 23.73 | G7: =dane_sprzedazy_sku__3[[#This Row],[Ilość wydana]]*dane_sprzedazy_sku__3[[#This Row],[Wartość jednostkowa]] -> 47.46
A8: SKU-0001 | B8: Segregator A4 Compact | C8: Artykuły biurowe | D8: 45689 | E8: 2 | F8: 22.78 | G8: =dane_sprzedazy_sku__3[[#This Row],[Ilość wydana]]*dane_sprzedazy_sku__3[[#This Row],[Wartość jednostkowa]] -> 45.56
A9: SKU-0001 | B9: Segregator A4 Compact | C9: Artykuły biurowe | D9: 45717 | E9: 2 | F9: 23.51 | G9: =dane_sprzedazy_sku__3[[#This Row],[Ilość wydana]]*dane_sprzedazy_sku__3[[#This Row],[Wartość jednostkowa]] -> 47.02
A10: SKU-0001 | B10: Segregator A4 Compact | C10: Artykuły biurowe | D10: 45748 | E10: 2 | F10: 22.91 | G10: =dane_sprzedazy_sku__3[[#This Row],[Ilość wydana]]*dane_sprzedazy_sku__3[[#This Row],[Wartość jednostkowa]] -> 45.82
A11: SKU-0001 | B11: Segregator A4 Compact | C11: Artykuły biurowe | D11: 45778 | E11: 2 | F11: 22.97 | G11: =dane_sprzedazy_sku__3[[#This Row],[Ilość wydana]]*dane_sprzedazy_sku__3[[#This Row],[Wartość jednostkowa]] -> 45.94
A12: SKU-0001 | B12: Segregator A4 Compact | C12: Artykuły biurowe | D12: 45809 | E12: 2 | F12: 24.16 | G12: =dane_sprzedazy_sku__3[[#This Row],[Ilość wydana]]*dane_sprzedazy_sku__3[[#This Row],[Wartość jednostkowa]] -> 48.32
A13: SKU-0001 | B13: Segregator A4 Compact | C13: Artykuły biurowe | D13: 45839 | E13: 2 | F13: 23.22 | G13: =dane_sprzedazy_sku__3[[#This Row],[Ilość wydana]]*dane_sprzedazy_sku__3[[#This Row],[Wartość jednostkowa]] -> 46.44
... A12001: SKU-0500 | B12001: Blender kielichowy | C12001: AGD | D12001: 46204 | E12001: 15 | F12001: 89.5 | G12001: =dane_sprzedazy_sku__3[[#This Row],[Ilość wydana]]*dane_sprzedazy_sku__3[[#This Row],[Wartość jednostkowa]] -> 1342.5

Sheet Pivot ABC (źródło)
A1: SKU | B1: Nazwa produktu | C1: Sum of Wartość sprzedaży
A2: SKU-0001 | B2: Segregator A4 Compact | C2: 1252.79
A3: SKU-0002 | B3: Herbata czarna 100g Pro | C3: 11094.77
A4: SKU-0003 | B4: Buty sportowe | C4: 11645.41
A5: SKU-0004 | B5: Czekolada mleczna Compact | C5: 700.89
A6: SKU-0005 | B6: Gra planszowa Compact | C6: 343418.58
A7: SKU-0006 | B7: Klapki basenowe Compact | C7: 71266
A8: SKU-0007 | B8: Hantle 5kg Compact | C8: 18791.52
A9: SKU-0008 | B9: Plecak trekkingowy Classic | C9: 58776.48
A10: SKU-0009 | B10: Długopis żelowy Mini | C10: 9025.63
A11: SKU-0010 | B11: Długopis żelowy XL | C11: 14327.12
A12: SKU-0011 | B12: Suszarka do włosów Mini | C12: 7695.89
A13: SKU-0012 | B13: Kosiarka elektryczna Advanced | C13: 37764.12
... A501: SKU-0500 | B501: Blender kielichowy | C501: 29965.82
A502: (blank) | B502: (blank)
A503: Grand Total | C503: 66324345

Sheet ABC Analysis
A1: SKU | B1: Nazwa produktu | C1: Sum of Wartość sprzedaży | D1: % udziału | E1: % skumulowany | F1: Klasa ABC | J1: ABC (wartość sprzedaży)
A2: SKU-0131 | B2: Odtwarzacz Blu-ray Compact | C2: 6546510.8 | D2: =C2/SUM($C$2:$C$501) -> 0.098704492 | E2: =D2 -> 0.098704492 | F2: =IF(E2<=0.8,"A",IF(E2<=0.95,"B","C")) -> A | I2: =COUNTIF(F:F,"A") -> 102 | J2: =I2/COUNTA($F$2:$F$501) -> 0.204 | K2: =SUMIF($F$2:$F$501,"A",$C$2:$C$501) -> 53009841
A3: SKU-0330 | B3: Soundbar Mini | C3: 3266186.4 | D3: =C3/SUM($C$2:$C$501) -> 0.049245664 | E3: =E2+D3 -> 0.14795016 | F3: =IF(E3<=0.8,"A",IF(E3<=0.95,"B","C")) -> A | I3: =COUNTIF(F:F,"B") -> 121 | J3: =I3/COUNTA($F$2:$F$501) -> 0.242 | K3: =SUMIF($F$2:$F$501,"B",$C$2:$C$501) -> 9992048.7
A4: SKU-0362 | B4: Parasol ogrodowy Premium | C4: 1992983.8 | D4: =C4/SUM($C$2:$C$501) -> 0.030049054 | E4: =E3+D4 -> 0.17799921 | F4: =IF(E4<=0.8,"A",IF(E4<=0.95,"B","C")) -> A | I4: =COUNTIF(F:F,"C") -> 277 | J4: =I4/COUNTA($F$2:$F$501) -> 0.554 | K4: =SUMIF($F$2:$F$501,"C",$C$2:$C$501) -> 3322454.8
A5: SKU-0146 | B5: Projektor LED | C5: 1827857.2 | D5: =C5/SUM($C$2:$C$501) -> 0.02755937 | E5: =E4+D5 -> 0.20555858 | F5: =IF(E5<=0.8,"A",IF(E5<=0.95,"B","C")) -> A
A6: SKU-0427 | B6: Odtwarzacz Blu-ray Eco | C6: 1468564.6 | D6: =C6/SUM($C$2:$C$501) -> 0.022142166 | E6: =E5+D6 -> 0.22770075 | F6: =IF(E6<=0.8,"A",IF(E6<=0.95,"B","C")) -> A
A7: SKU-0301 | B7: Projektor LED Eco | C7: 1437870.4 | D7: =C7/SUM($C$2:$C$501) -> 0.021679376 | E7: =E6+D7 -> 0.24938012 | F7: =IF(E7<=0.8,"A",IF(E7<=0.95,"B","C")) -> A
A8: SKU-0294 | B8: Projektor LED XL | C8: 1417802.2 | D8: =C8/SUM($C$2:$C$501) -> 0.021376799 | E8: =E7+D8 -> 0.27075692 | F8: =IF(E8<=0.8,"A",IF(E8<=0.95,"B","C")) -> A
A9: SKU-0328 | B9: Płyn do spryskiwaczy Plus | C9: 1244047.9 | D9: =C9/SUM($C$2:$C$501) -> 0.018757032 | E9: =E8+D9 -> 0.28951395 | F9: =IF(E9<=0.8,"A",IF(E9<=0.95,"B","C")) -> A
A10: SKU-0036 | B10: Biurko komputerowe | C10: 1183829.1 | D10: =C10/SUM($C$2:$C$501) -> 0.017849089 | E10: =E9+D10 -> 0.30736304 | F10: =IF(E10<=0.8,"A",IF(E10<=0.95,"B","C")) -> A
A11: SKU-0214 | B11: Antena DVB-T Pro | C11: 1108527.8 | D11: =C11/SUM($C$2:$C$501) -> 0.016713739 | E11: =E10+D11 -> 0.32407678 | F11: =IF(E11<=0.8,"A",IF(E11<=0.95,"B","C")) -> A
A12: SKU-0396 | B12: Robot kuchenny Advanced | C12: 991158.11 | D12: =C12/SUM($C$2:$C$501) -> 0.014944107 | E12: =E11+D12 -> 0.33902089 | F12: =IF(E12<=0.8,"A",IF(E12<=0.95,"B","C")) -> A
A13: SKU-0149 | B13: Młotek stolarski Plus | C13: 876947.66 | D13: =C13/SUM($C$2:$C$501) -> 0.013222108 | E13: =E12+D13 -> 0.352243 | F13: =IF(E13<=0.8,"A",IF(E13<=0.95,"B","C")) -> A
A14: SKU-0070 | B14: Ładowarka sieciowa | C14: 779772.49 | D14: =C14/SUM($C$2:$C$501) -> 0.011756957 | E14: =E13+D14 -> 0.36399995 | F14: =IF(E14<=0.8,"A",IF(E14<=0.95,"B","C")) -> A
A15: SKU-0092 | B15: Nawóz uniwersalny Advanced | C15: 769722.25 | D15: =C15/SUM($C$2:$C$501) -> 0.011605426 | E15: =E14+D15 -> 0.37560538 | F15: =IF(E15<=0.8,"A",IF(E15<=0.95,"B","C")) -> A
A16: SKU-0068 | B16: Fotel wypoczynkowy Mini | C16: 686532.69 | D16: =C16/SUM($C$2:$C$501) -> 0.010351142 | E16: =E15+D16 -> 0.38595652 | F16: =IF(E16<=0.8,"A",IF(E16<=0.95,"B","C")) -> A
... A39: SKU-0309 | B39: Wycieraczki samochodowe XL | C39: 392861.29 | D39: =C39/SUM($C$2:$C$501) -> 0.0059233346 | E39: =E38+D39 -> 0.56302786 | F39: =IF(E39<=0.8,"A",IF(E39<=0.95,"B","C")) -> A
A40: SKU-0432 | B40: Biurko komputerowe Pro | C40: 386677.91 | D40: =C40/SUM($C$2:$C$501) -> 0.0058301052 | E40: =E39+D40 -> 0.56885796 | F40: =IF(E40<=0.8,"A",IF(E40<=0.95,"B","C")) -> A | O40: A
A41: SKU-0129 | B41: Odświeżacz powietrza do auta Plus | C41: 373815.93 | D41: =C41/SUM($C$2:$C$501) -> 0.0056361797 | E41: =E40+D41 -> 0.57449414 | F41: =IF(E41<=0.8,"A",IF(E41<=0.95,"B","C")) -> A
A42: SKU-0199 | B42: Biurko komputerowe Advanced | C42: 371306.11 | D42: =C42/SUM($C$2:$C$501) -> 0.0055983381 | E42: =E41+D42 -> 0.58009248 | F42: =IF(E42<=0.8,"A",IF(E42<=0.95,"B","C")) -> A
A43: SKU-0481 | B43: Grill węglowy Advanced | C43: 368653.56 | D43: =C43/SUM($C$2:$C$501) -> 0.0055583445 | E43: =E42+D43 -> 0.58565082 | F43: =IF(E43<=0.8,"A",IF(E43<=0.95,"B","C")) -> A
A44: SKU-0494 | B44: Kamera sportowa Compact | C44: 367074.19 | D44: =C44/SUM($C$2:$C$501) -> 0.0055345317 | E44: =E43+D44 -> 0.59118536 | F44: =IF(E44<=0.8,"A",IF(E44<=0.95,"B","C")) -> A
A45: SKU-0018 | B45: Doniczka ceramiczna Pro | C45: 363107.54 | D45: =C45/SUM($C$2:$C$501) -> 0.0054747249 | E45: =E44+D45 -> 0.59666008 | F45: =IF(E45<=0.8,"A",IF(E45<=0.95,"B","C")) -> A
A46: SKU-0440 | B46: Toster Advanced | C46: 350764.77 | D46: =C46/SUM($C$2:$C$501) -> 0.0052886277 | E46: =E45+D46 -> 0.60194871 | F46: =IF(E46<=0.8,"A",IF(E46<=0.95,"B","C")) -> A
A47: SKU-0005 | B47: Gra planszowa Compact | C47: 343418.58 | D47: =C47/SUM($C$2:$C$501) -> 0.0051778661 | E47: =E46+D47 -> 0.60712657 | F47: =IF(E47<=0.8,"A",IF(E47<=0.95,"B","C")) -> A
A48: SKU-0074 | B48: Sandały letnie Mini | C48: 342181.88 | D48: =C48/SUM($C$2:$C$501) -> 0.0051592199 | E48: =E47+D48 -> 0.61228579 | F48: =IF(E48<=0.8,"A",IF(E48<=0.95,"B","C")) -> A
A49: SKU-0483 | B49: Osłona przeciwsłoneczna Mini | C49: 336806.35 | D49: =C49/SUM($C$2:$C$501) -> 0.0050781708 | E49: =E48+D49 -> 0.61736397 | F49: =IF(E49<=0.8,"A",IF(E49<=0.95,"B","C")) -> A
A50: SKU-0467 | B50: Puzzle 1000 elementów Eco | C50: 335217.97 | D50: =C50/SUM($C$2:$C$501) -> 0.0050542221 | E50: =E49+D50 -> 0.62241819 | F50: =IF(E50<=0.8,"A",IF(E50<=0.95,"B","C")) -> A
A51: SKU-0120 | B51: Piłka do piłki nożnej Compact | C51: 330307.26 | D51: =C51/SUM($C$2:$C$501) -> 0.0049801813 | E51: =E50+D51 -> 0.62739837 | F51: =IF(E51<=0.8,"A",IF(E51<=0.95,"B","C")) -> A
A52: SKU-0264 | B52: Robot kuchenny Plus | C52: 315708.8 | D52: =C52/SUM($C$2:$C$501) -> 0.0047600741 | E52: =E51+D52 -> 0.63215844 | F52: =IF(E52<=0.8,"A",IF(E52<=0.95,"B","C")) -> A
... A501: SKU-0280 | B501: Kalkulator naukowy Advanced | C501: 113.76 | D501: =C501/SUM($C$2:$C$501) -> 1.7152073e-06 | E501: =E500+D501 -> 1 | F501: =IF(E501<=0.8,"A",IF(E501<=0.95,"B","C")) -> C
A502: Grand Total | C502: 66324345

Sheet Pivot XYZ (źródło)
A3: Sum of Ilość wydana | B3: Column Labels
B4: 2024 | G4: 2025 | S4: 2026 | Z4: Grand Total
A5: Row Labels | B5: sie | C5: wrz | D5: paź | E5: lis | F5: gru | G5: sty | H5: lut | I5: mar | J5: kwi | K5: maj | L5: cze | M5: lip | N5: sie | O5: wrz | P5: paź | Q5: lis | R5: gru | S5: sty | T5: lut | U5: mar | V5: kwi | W5: maj | X5: cze | Y5: lip
A6: SKU-0001 | B6: 2 | C6: 2 | D6: 2 | E6: 2 | F6: 2 | G6: 2 | H6: 2 | I6: 2 | J6: 2 | K6: 2 | L6: 2 | M6: 2 | N6: 2 | O6: 2 | P6: 2 | Q6: 3 | R6: 2 | S6: 2 | T6: 2 | U6: 3 | V6: 3 | W6: 3 | X6: 3 | Y6: 2 | Z6: 53
A7: SKU-0002 | B7: 13 | C7: 14 | D7: 13 | E7: 13 | F7: 13 | G7: 15 | H7: 13 | I7: 12 | J7: 10 | K7: 12 | L7: 11 | M7: 11 | N7: 12 | O7: 12 | P7: 16 | Q7: 13 | R7: 15 | S7: 17 | T7: 16 | U7: 13 | V7: 12 | W7: 12 | X7: 12 | Y7: 9 | Z7: 309
A8: SKU-0003 | B8: 9 | C8: 6 | D8: 5 | E8: 3 | F8: 3 | G8: 2 | H8: 1 | I8: 2 | J8: 4 | K8: 7 | L8: 8 | M8: 7 | N8: 8 | O8: 8 | P8: 6 | Q8: 5 | R8: 2 | S8: 1 | T8: 2 | U8: 3 | V8: 4 | W8: 7 | X8: 8 | Y8: 10 | Z8: 121
A9: SKU-0004 | B9: 3 | C9: 2 | D9: 3 | E9: 3 | F9: 3 | G9: 2 | H9: 3 | I9: 3 | J9: 3 | K9: 3 | L9: 3 | M9: 3 | N9: 3 | O9: 3 | P9: 3 | Q9: 3 | R9: 3 | S9: 3 | T9: 3 | U9: 3 | V9: 4 | W9: 3 | X9: 4 | Y9: 4 | Z9: 73
A10: SKU-0005 | B10: 249 | C10: 304 | D10: 288 | E10: 284 | F10: 254 | G10: 214 | H10: 248 | I10: 230 | J10: 173 | K10: 218 | L10: 264 | M10: 270 | N10: 249 | O10: 231 | P10: 253 | Q10: 216 | R10: 223 | S10: 220 | T10: 190 | U10: 191 | V10: 191 | W10: 188 | X10: 199 | Y10: 210 | Z10: 5557
A11: SKU-0006 | B11: 0 | C11: 24 | D11: 0 | E11: 10 | F11: 0 | G11: 6 | H11: 10 | I11: 5 | J11: 0 | K11: 0 | L11: 17 | M11: 0 | N11: 40 | O11: 13 | P11: 18 | Q11: 0 | R11: 10 | S11: 0 | T11: 15 | U11: 8 | V11: 10 | W11: 11 | X11: 0 | Y11: 15 | Z11: 212
A12: SKU-0007 | B12: 2 | C12: 2 | D12: 3 | E12: 4 | F12: 4 | G12: 3 | H12: 3 | I12: 3 | J12: 1 | K12: 1 | L12: 1 | M12: 1 | N12: 1 | O12: 2 | P12: 3 | Q12: 4 | R12: 3 | S12: 4 | T12: 3 | U12: 1 | V12: 1 | W12: 2 | X12: 1 | Y12: 1 | Z12: 54
A13: SKU-0008 | B13: 5 | C13: 4 | D13: 2 | E13: 3 | F13: 4 | G13: 7 | H13: 9 | I13: 12 | J13: 14 | K13: 11 | L13: 12 | M13: 11 | N13: 4 | O13: 3 | P13: 2 | Q13: 2 | R13: 3 | S13: 2 | T13: 9 | U13: 14 | V13: 9 | W13: 15 | X13: 12 | Y13: 6 | Z13: 175
A14: SKU-0009 | B14: 0 | C14: 11 | D14: 0 | E14: 0 | F14: 19 | G14: 11 | H14: 12 | I14: 19 | J14: 9 | K14: 0 | L14: 0 | M14: 17 | N14: 0 | O14: 2 | P14: 0 | Q14: 4 | R14: 0 | S14: 1 | T14: 8 | U14: 17 | V14: 0 | W14: 0 | X14: 7 | Y14: 19 | Z14: 156
A15: SKU-0010 | B15: 13 | C15: 21 | D15: 30 | E15: 30 | F15: 35 | G15: 45 | H15: 51 | I15: 22 | J15: 21 | K15: 17 | L15: 12 | M15: 11 | N15: 12 | O15: 17 | P15: 38 | Q15: 37 | R15: 46 | S15: 54 | T15: 38 | U15: 52 | V15: 36 | W15: 21 | X15: 13 | Y15: 13 | Z15: 685
A16: SKU-0011 | B16: 2 | C16: 3 | D16: 2 | E16: 3 | F16: 5 | G16: 4 | H16: 0 | I16: 3 | J16: 2 | K16: 0 | L16: 0 | M16: 0 | N16: 3 | O16: 0 | P16: 0 | Q16: 0 | R16: 3 | S16: 3 | T16: 0 | U16: 1 | V16: 2 | W16: 0 | X16: 2 | Y16: 0 | Z16: 38
A17: SKU-0012 | B17: 7 | C17: 9 | D17: 11 | E17: 11 | F17: 11 | G17: 11 | H17: 12 | I17: 14 | J17: 12 | K17: 12 | L17: 13 | M17: 12 | N17: 10 | O17: 12 | P17: 12 | Q17: 14 | R17: 12 | S17: 12 | T17: 15 | U17: 15 | V17: 13 | W17: 13 | X17: 14 | Y17: 13 | Z17: 290
... A506: Grand Total | B506: 9391 | C506: 9538 | D506: 9605 | E506: 10770 | F506: 11151 | G506: 10864 | H506: 9739 | I506: 9502 | J506: 10236 | K506: 10792 | L506: 10870 | M506: 11205 | N506: 10188 | O506: 9761 | P506: 10314 | Q506: 10727 | R506: 10946 | S506: 12356 | T506: 11472 | U506: 11300 | V506: 11154 | W506: 10159 | X506: 10800 | Y506: 10331 | Z506: 253171

Sheet XYZ Analysis
A1: Sum of Ilość wydana | B1: Column Labels | Z1: Średnia | AA1: Odch_std | AB1: Współczynnik zmienności (CV) | AC1: Klasa XYZ
B2: 2024 | G2: 2025 | S2: 2026 | AD2: =COUNTIF(AC4:AC503,"X") -> 200 | AE2: Liczba SKU: X
A3: Row Labels | B3: sie | C3: wrz | D3: paź | E3: lis | F3: gru | G3: sty | H3: lut | I3: mar | J3: kwi | K3: maj | L3: cze | M3: lip | N3: sie | O3: wrz | P3: paź | Q3: lis | R3: gru | S3: sty | T3: lut | U3: mar | V3: kwi | W3: maj | X3: cze | Y3: lip | AD3: =COUNTIF(AC4:AC503,"Y") -> 209 | AE3: Liczba SKU: Y
A4: SKU-0001 | B4: 2 | C4: 2 | D4: 2 | E4: 2 | F4: 2 | G4: 2 | H4: 2 | I4: 2 | J4: 2 | K4: 2 | L4: 2 | M4: 2 | N4: 2 | O4: 2 | P4: 2 | Q4: 3 | R4: 2 | S4: 2 | T4: 2 | U4: 3 | V4: 3 | W4: 3 | X4: 3 | Y4: 2 | Z4: =AVERAGE(B4:Y4) -> 2.2083333 | AA4: =_xlfn.STDEV.P(B4:Y4) -> 0.40611643 | AB4: =AA4/Z4 -> 0.18390178 | AC4: =IF(AB4<=0.5,"X",IF(AB4<=1,"Y","Z")) -> X | AD4: =COUNTIF(AC4:AC503,"Z") -> 91 | AE4: Liczba SKU: Z
A5: SKU-0002 | B5: 13 | C5: 14 | D5: 13 | E5: 13 | F5: 13 | G5: 15 | H5: 13 | I5: 12 | J5: 10 | K5: 12 | L5: 11 | M5: 11 | N5: 12 | O5: 12 | P5: 16 | Q5: 13 | R5: 15 | S5: 17 | T5: 16 | U5: 13 | V5: 12 | W5: 12 | X5: 12 | Y5: 9 | Z5: =AVERAGE(B5:Y5) -> 12.875 | AA5: =_xlfn.STDEV.P(B5:Y5) -> 1.8554537 | AB5: =AA5/Z5 -> 0.14411291 | AC5: =IF(AB5<=0.5,"X",IF(AB5<=1,"Y","Z")) -> X
A6: SKU-0003 | B6: 9 | C6: 6 | D6: 5 | E6: 3 | F6: 3 | G6: 2 | H6: 1 | I6: 2 | J6: 4 | K6: 7 | L6: 8 | M6: 7 | N6: 8 | O6: 8 | P6: 6 | Q6: 5 | R6: 2 | S6: 1 | T6: 2 | U6: 3 | V6: 4 | W6: 7 | X6: 8 | Y6: 10 | Z6: =AVERAGE(B6:Y6) -> 5.0416667 | AA6: =_xlfn.STDEV.P(B6:Y6) -> 2.6845106 | AB6: =AA6/Z6 -> 0.53246491 | AC6: =IF(AB6<=0.5,"X",IF(AB6<=1,"Y","Z")) -> Y
A7: SKU-0004 | B7: 3 | C7: 2 | D7: 3 | E7: 3 | F7: 3 | G7: 2 | H7: 3 | I7: 3 | J7: 3 | K7: 3 | L7: 3 | M7: 3 | N7: 3 | O7: 3 | P7: 3 | Q7: 3 | R7: 3 | S7: 3 | T7: 3 | U7: 3 | V7: 4 | W7: 3 | X7: 4 | Y7: 4 | Z7: =AVERAGE(B7:Y7) -> 3.0416667 | AA7: =_xlfn.STDEV.P(B7:Y7) -> 0.45452967 | AB7: =AA7/Z7 -> 0.14943441 | AC7: =IF(AB7<=0.5,"X",IF(AB7<=1,"Y","Z")) -> X
A8: SKU-0005 | B8: 249 | C8: 304 | D8: 288 | E8: 284 | F8: 254 | G8: 214 | H8: 248 | I8: 230 | J8: 173 | K8: 218 | L8: 264 | M8: 270 | N8: 249 | O8: 231 | P8: 253 | Q8: 216 | R8: 223 | S8: 220 | T8: 190 | U8: 191 | V8: 191 | W8: 188 | X8: 199 | Y8: 210 | Z8: =AVERAGE(B8:Y8) -> 231.54167 | AA8: =_xlfn.STDEV.P(B8:Y8) -> 34.380202 | AB8: =AA8/Z8 -> 0.14848387 | AC8: =IF(AB8<=0.5,"X",IF(AB8<=1,"Y","Z")) -> X
A9: SKU-0006 | B9: 0 | C9: 24 | D9: 0 | E9: 10 | F9: 0 | G9: 6 | H9: 10 | I9: 5 | J9: 0 | K9: 0 | L9: 17 | M9: 0 | N9: 40 | O9: 13 | P9: 18 | Q9: 0 | R9: 10 | S9: 0 | T9: 15 | U9: 8 | V9: 10 | W9: 11 | X9: 0 | Y9: 15 | Z9: =AVERAGE(B9:Y9) -> 8.8333333 | AA9: =_xlfn.STDEV.P(B9:Y9) -> 9.5335664 | AB9: =AA9/Z9 -> 1.0792717 | AC9: =IF(AB9<=0.5,"X",IF(AB9<=1,"Y","Z")) -> Z
A10: SKU-0007 | B10: 2 | C10: 2 | D10: 3 | E10: 4 | F10: 4 | G10: 3 | H10: 3 | I10: 3 | J10: 1 | K10: 1 | L10: 1 | M10: 1 | N10: 1 | O10: 2 | P10: 3 | Q10: 4 | R10: 3 | S10: 4 | T10: 3 | U10: 1 | V10: 1 | W10: 2 | X10: 1 | Y10: 1 | Z10: =AVERAGE(B10:Y10) -> 2.25 | AA10: =_xlfn.STDEV.P(B10:Y10) -> 1.1273124 | AB10: =AA10/Z10 -> 0.50102775 | AC10: =IF(AB10<=0.5,"X",IF(AB10<=1,"Y","Z")) -> Y
A11: SKU-0008 | B11: 5 | C11: 4 | D11: 2 | E11: 3 | F11: 4 | G11: 7 | H11: 9 | I11: 12 | J11: 14 | K11: 11 | L11: 12 | M11: 11 | N11: 4 | O11: 3 | P11: 2 | Q11: 2 | R11: 3 | S11: 2 | T11: 9 | U11: 14 | V11: 9 | W11: 15 | X11: 12 | Y11: 6 | Z11: =AVERAGE(B11:Y11) -> 7.2916667 | AA11: =_xlfn.STDEV.P(B11:Y11) -> 4.3730154 | AB11: =AA11/Z11 -> 0.59972783 | AC11: =IF(AB11<=0.5,"X",IF(AB11<=1,"Y","Z")) -> Y
A12: SKU-0009 | B12: 0 | C12: 11 | D12: 0 | E12: 0 | F12: 19 | G12: 11 | H12: 12 | I12: 19 | J12: 9 | K12: 0 | L12: 0 | M12: 17 | N12: 0 | O12: 2 | P12: 0 | Q12: 4 | R12: 0 | S12: 1 | T12: 8 | U12: 17 | V12: 0 | W12: 0 | X12: 7 | Y12: 19 | Z12: =AVERAGE(B12:Y12) -> 6.5 | AA12: =_xlfn.STDEV.P(B12:Y12) -> 7.2111026 | AB12: =AA12/Z12 -> 1.1094004 | AC12: =IF(AB12<=0.5,"X",IF(AB12<=1,"Y","Z")) -> Z
A13: SKU-0010 | B13: 13 | C13: 21 | D13: 30 | E13: 30 | F13: 35 | G13: 45 | H13: 51 | I13: 22 | J13: 21 | K13: 17 | L13: 12 | M13: 11 | N13: 12 | O13: 17 | P13: 38 | Q13: 37 | R13: 46 | S13: 54 | T13: 38 | U13: 52 | V13: 36 | W13: 21 | X13: 13 | Y13: 13 | Z13: =AVERAGE(B13:Y13) -> 28.541667 | AA13: =_xlfn.STDEV.P(B13:Y13) -> 13.979089 | AB13: =AA13/Z13 -> 0.4897783 | AC13: =IF(AB13<=0.5,"X",IF(AB13<=1,"Y","Z")) -> X
A14: SKU-0011 | B14: 2 | C14: 3 | D14: 2 | E14: 3 | F14: 5 | G14: 4 | H14: 0 | I14: 3 | J14: 2 | K14: 0 | L14: 0 | M14: 0 | N14: 3 | O14: 0 | P14: 0 | Q14: 0 | R14: 3 | S14: 3 | T14: 0 | U14: 1 | V14: 2 | W14: 0 | X14: 2 | Y14: 0 | Z14: =AVERAGE(B14:Y14) -> 1.5833333 | AA14: =_xlfn.STDEV.P(B14:Y14) -> 1.5252504 | AB14: =AA14/Z14 -> 0.96331606 | AC14: =IF(AB14<=0.5,"X",IF(AB14<=1,"Y","Z")) -> Y
A15: SKU-0012 | B15: 7 | C15: 9 | D15: 11 | E15: 11 | F15: 11 | G15: 11 | H15: 12 | I15: 14 | J15: 12 | K15: 12 | L15: 13 | M15: 12 | N15: 10 | O15: 12 | P15: 12 | Q15: 14 | R15: 12 | S15: 12 | T15: 15 | U15: 15 | V15: 13 | W15: 13 | X15: 14 | Y15: 13 | Z15: =AVERAGE(B15:Y15) -> 12.083333 | AA15: =_xlfn.STDEV.P(B15:Y15) -> 1.7775608 | AB15: =AA15/Z15 -> 0.14710848 | AC15: =IF(AB15<=0.5,"X",IF(AB15<=1,"Y","Z")) -> X
A16: SKU-0013 | B16: 7 | C16: 7 | D16: 6 | E16: 7 | F16: 7 | G16: 7 | H16: 8 | I16: 8 | J16: 7 | K16: 9 | L16: 7 | M16: 7 | N16: 5 | O16: 7 | P16: 6 | Q16: 5 | R16: 7 | S16: 7 | T16: 8 | U16: 9 | V16: 8 | W16: 9 | X16: 7 | Y16: 7 | Z16: =AVERAGE(B16:Y16) -> 7.1666667 | AA16: =_xlfn.STDEV.P(B16:Y16) -> 1.0274023 | AB16: =AA16/Z16 -> 0.14335847 | AC16: =IF(AB16<=0.5,"X",IF(AB16<=1,"Y","Z")) -> X
... A503: SKU-0500 | B503: 7 | C503: 2 | D503: 0 | E503: 2 | F503: 7 | G503: 15 | H503: 26 | I503: 24 | J503: 31 | K503: 25 | L503: 22 | M503: 14 | N503: 6 | O503: 3 | P503: 0 | Q503: 2 | R503: 5 | S503: 13 | T503: 18 | U503: 19 | V503: 26 | W503: 37 | X503: 23 | Y503: 15 | Z503: =AVERAGE(B503:Y503) -> 14.25 | AA503: =_xlfn.STDEV.P(B503:Y503) -> 10.611511 | AB503: =AA503/Z503 -> 0.74466744 | AC503: =IF(AB503<=0.5,"X",IF(AB503<=1,"Y","Z")) -> Y
A504: Grand Total | B504: 9391 | C504: 9538 | D504: 9605 | E504: 10770 | F504: 11151 | G504: 10864 | H504: 9739 | I504: 9502 | J504: 10236 | K504: 10792 | L504: 10870 | M504: 11205 | N504: 10188 | O504: 9761 | P504: 10314 | Q504: 10727 | R504: 10946 | S504: 12356 | T504: 11472 | U504: 11300 | V504: 11154 | W504: 10159 | X504: 10800 | Y504: 10331 | Z504: 253171

Sheet Matrix ABC-XYZ
A1: SKU | B1: Klasa ABC | C1: Klasa XYZ | D1: Kombinacja | E1: Poziom obsługi | F1: Polityka zapasów | G1: Lead Time (dni) | H1: Kategoria | I1: Dane pomocnicze | K1: Kombinacja | L1: Poziom obsługi | M1: Polityka zapasów | N1: koszt zamówienia | O1: koszt utrzymania zapasu (rocznie) | P1: Wartość jednostkowa (zł) | Q1: Średni popyt miesięczny (szt.) | R1: Średni popyt dzienny (szt.) | S1: Odchylenie std. miesięczne | T1: Odchylenie std. dzienne | U1: Safety Stock (szt.) | V1: Reorder Point (szt.) | W1: EOQ (szt.)
A2: SKU-0131 | B2: =_xlfn.XLOOKUP(A2, 'ABC Analysis'!A:A, 'ABC Analysis'!F:F) -> A | C2: =_xlfn.XLOOKUP(A2,'XYZ Analysis'!A:A,'XYZ Analysis'!AC:AC) -> X | D2: =B2&C2 -> AX | E2: =_xlfn.XLOOKUP(D2,K:K,L:L) -> 0.99 | F2: =_xlfn.XLOOKUP(D2,K:K,M:M) -> Niski zapas bezpieczeństwa, częste zamówienia małymi partiami | G2: =_xlfn.XLOOKUP(H2,$I$2:$I$16,$J$2:$J$16) -> 14 | H2: =_xlfn.XLOOKUP(A2,Data!A:A,Data!C:C) -> RTV | I2: Elektronika | J2: 10 | K2: AX | L2: 0.99 | M2: Niski zapas bezpieczeństwa, częste zamówienia małymi partiami | N2: 80 | O2: 0.22 | P2: =_xlfn.XLOOKUP(A2,Data!A:A,Data!F:F) -> 977.78 | Q2: {=_xlfn.XLOOKUP(A2,'XYZ Analysis'!A:A,'XYZ Analysis'!$Z:Z)} -> 278.41667 | R2: =Q2/30 -> 9.2805556 | S2: =_xlfn.XLOOKUP(A2,'XYZ Analysis'!A:A,'XYZ Analysis'!AA:AA) -> 138.29887 | T2: =S2/30 -> 4.6099622 | U2: =ROUNDUP(_xlfn.NORM.S.INV(E2)*T2*SQRT(G2),0) -> 41 | V2: =R2*G2+U2 -> 170.92778 | W2: =SQRT(2*R2*365*$N$2/($N$2*P2)) -> 2.6322543
A3: SKU-0330 | B3: =_xlfn.XLOOKUP(A3, 'ABC Analysis'!A:A, 'ABC Analysis'!F:F) -> A | C3: =_xlfn.XLOOKUP(A3,'XYZ Analysis'!A:A,'XYZ Analysis'!AC:AC) -> Y | D3: =B3&C3 -> AY | E3: =_xlfn.XLOOKUP(D3,K:K,L:L) -> 0.97 | F3: =_xlfn.XLOOKUP(D3,K:K,M:M) -> Umiarkowany zapas bezpieczeństwa, zamówienia dostosowane do sezonowości | G3: =_xlfn.XLOOKUP(H3,$I$2:$I$16,$J$2:$J$16) -> 14 | H3: =_xlfn.XLOOKUP(A3,Data!A:A,Data!C:C) -> RTV | I3: AGD | J3: 12 | K3: AY | L3: 0.97 | M3: Umiarkowany zapas bezpieczeństwa, zamówienia dostosowane do sezonowości | P3: =_xlfn.XLOOKUP(A3,Data!A:A,Data!F:F) -> 1110.63 | Q3: {=_xlfn.XLOOKUP(A3,'XYZ Analysis'!A:A,'XYZ Analysis'!$Z:Z)} -> 123.08333 | R3: =Q3/30 -> 4.1027778 | S3: =_xlfn.XLOOKUP(A3,'XYZ Analysis'!A:A,'XYZ Analysis'!AA:AA) -> 100.70953 | T3: =S3/30 -> 3.3569844 | U3: =ROUNDUP(_xlfn.NORM.S.INV(E3)*T3*SQRT(G3),0) -> 24 | V3: =R3*G3+U3 -> 81.438889 | W3: =SQRT(2*R3*365*$N$2/($N$2*P3)) -> 1.642161
A4: SKU-0362 | B4: =_xlfn.XLOOKUP(A4, 'ABC Analysis'!A:A, 'ABC Analysis'!F:F) -> A | C4: =_xlfn.XLOOKUP(A4,'XYZ Analysis'!A:A,'XYZ Analysis'!AC:AC) -> Z | D4: =B4&C4 -> AZ | E4: =_xlfn.XLOOKUP(D4,K:K,L:L) -> 0.95 | F4: =_xlfn.XLOOKUP(D4,K:K,M:M) -> Wysoki zapas bezpieczeństwa mimo wysokiego kosztu | G4: =_xlfn.XLOOKUP(H4,$I$2:$I$16,$J$2:$J$16) -> 12 | H4: =_xlfn.XLOOKUP(A4,Data!A:A,Data!C:C) -> Ogród | I4: RTV | J4: 14 | K4: AZ | L4: 0.95 | M4: Wysoki zapas bezpieczeństwa mimo wysokiego kosztu | P4: =_xlfn.XLOOKUP(A4,Data!A:A,Data!F:F) -> 350.11 | Q4: {=_xlfn.XLOOKUP(A4,'XYZ Analysis'!A:A,'XYZ Analysis'!$Z:Z)} -> 226.5 | R4: =Q4/30 -> 7.55 | S4: =_xlfn.XLOOKUP(A4,'XYZ Analysis'!A:A,'XYZ Analysis'!AA:AA) -> 257.58736 | T4: =S4/30 -> 8.5862455 | U4: =ROUNDUP(_xlfn.NORM.S.INV(E4)*T4*SQRT(G4),0) -> 49 | V4: =R4*G4+U4 -> 139.6 | W4: =SQRT(2*R4*365*$N$2/($N$2*P4)) -> 3.9676435
A5: SKU-0146 | B5: =_xlfn.XLOOKUP(A5, 'ABC Analysis'!A:A, 'ABC Analysis'!F:F) -> A | C5: =_xlfn.XLOOKUP(A5,'XYZ Analysis'!A:A,'XYZ Analysis'!AC:AC) -> Y | D5: =B5&C5 -> AY | E5: =_xlfn.XLOOKUP(D5,K:K,L:L) -> 0.97 | F5: =_xlfn.XLOOKUP(D5,K:K,M:M) -> Umiarkowany zapas bezpieczeństwa, zamówienia dostosowane do sezonowości | G5: =_xlfn.XLOOKUP(H5,$I$2:$I$16,$J$2:$J$16) -> 14 | H5: =_xlfn.XLOOKUP(A5,Data!A:A,Data!C:C) -> RTV | I5: Odzież | J5: 7 | K5: BX | L5: 0.95 | M5: Niski-umiarkowany zapas bezpieczeństwa, standardowe zamówienia | P5: =_xlfn.XLOOKUP(A5,Data!A:A,Data!F:F) -> 840.56 | Q5: {=_xlfn.XLOOKUP(A5,'XYZ Analysis'!A:A,'XYZ Analysis'!$Z:Z)} -> 88.958333 | R5: =Q5/30 -> 2.9652778 | S5: =_xlfn.XLOOKUP(A5,'XYZ Analysis'!A:A,'XYZ Analysis'!AA:AA) -> 47.297356 | T5: =S5/30 -> 1.5765785 | U5: =ROUNDUP(_xlfn.NORM.S.INV(E5)*T5*SQRT(G5),0) -> 12 | V5: =R5*G5+U5 -> 53.513889 | W5: =SQRT(2*R5*365*$N$2/($N$2*P5)) -> 1.6047588
A6: SKU-0427 | B6: =_xlfn.XLOOKUP(A6, 'ABC Analysis'!A:A, 'ABC Analysis'!F:F) -> A | C6: =_xlfn.XLOOKUP(A6,'XYZ Analysis'!A:A,'XYZ Analysis'!AC:AC) -> Y | D6: =B6&C6 -> AY | E6: =_xlfn.XLOOKUP(D6,K:K,L:L) -> 0.97 | F6: =_xlfn.XLOOKUP(D6,K:K,M:M) -> Umiarkowany zapas bezpieczeństwa, zamówienia dostosowane do sezonowości | G6: =_xlfn.XLOOKUP(H6,$I$2:$I$16,$J$2:$J$16) -> 14 | H6: =_xlfn.XLOOKUP(A6,Data!A:A,Data!C:C) -> RTV | I6: Obuwie | J6: 9 | K6: BY | L6: 0.92 | M6: Umiarkowany zapas bezpieczeństwa, monitoruj sezonowość | P6: =_xlfn.XLOOKUP(A6,Data!A:A,Data!F:F) -> 1451.53 | Q6: {=_xlfn.XLOOKUP(A6,'XYZ Analysis'!A:A,'XYZ Analysis'!$Z:Z)} -> 40.541667 | R6: =Q6/30 -> 1.3513889 | S6: =_xlfn.XLOOKUP(A6,'XYZ Analysis'!A:A,'XYZ Analysis'!AA:AA) -> 26.361239 | T6: =S6/30 -> 0.87870797 | U6: =ROUNDUP(_xlfn.NORM.S.INV(E6)*T6*SQRT(G6),0) -> 7 | V6: =R6*G6+U6 -> 25.919444 | W6: =SQRT(2*R6*365*$N$2/($N$2*P6)) -> 0.82440116
A7: SKU-0301 | B7: =_xlfn.XLOOKUP(A7, 'ABC Analysis'!A:A, 'ABC Analysis'!F:F) -> A | C7: =_xlfn.XLOOKUP(A7,'XYZ Analysis'!A:A,'XYZ Analysis'!AC:AC) -> Y | D7: =B7&C7 -> AY | E7: =_xlfn.XLOOKUP(D7,K:K,L:L) -> 0.97 | F7: =_xlfn.XLOOKUP(D7,K:K,M:M) -> Umiarkowany zapas bezpieczeństwa, zamówienia dostosowane do sezonowości | G7: =_xlfn.XLOOKUP(H7,$I$2:$I$16,$J$2:$J$16) -> 14 | H7: =_xlfn.XLOOKUP(A7,Data!A:A,Data!C:C) -> RTV | I7: Kosmetyki | J7: 6 | K7: BZ | L7: 0.9 | M7: Podwyższony zapas bezpieczeństwa lub częstszy przegląd | P7: =_xlfn.XLOOKUP(A7,Data!A:A,Data!F:F) -> 723.18 | Q7: {=_xlfn.XLOOKUP(A7,'XYZ Analysis'!A:A,'XYZ Analysis'!$Z:Z)} -> 86.5 | R7: =Q7/30 -> 2.8833333 | S7: =_xlfn.XLOOKUP(A7,'XYZ Analysis'!A:A,'XYZ Analysis'!AA:AA) -> 79.100674 | T7: =S7/30 -> 2.6366891 | U7: =ROUNDUP(_xlfn.NORM.S.INV(E7)*T7*SQRT(G7),0) -> 19 | V7: =R7*G7+U7 -> 59.366667 | W7: =SQRT(2*R7*365*$N$2/($N$2*P7)) -> 1.706026
A8: SKU-0294 | B8: =_xlfn.XLOOKUP(A8, 'ABC Analysis'!A:A, 'ABC Analysis'!F:F) -> A | C8: =_xlfn.XLOOKUP(A8,'XYZ Analysis'!A:A,'XYZ Analysis'!AC:AC) -> Y | D8: =B8&C8 -> AY | E8: =_xlfn.XLOOKUP(D8,K:K,L:L) -> 0.97 | F8: =_xlfn.XLOOKUP(D8,K:K,M:M) -> Umiarkowany zapas bezpieczeństwa, zamówienia dostosowane do sezonowości | G8: =_xlfn.XLOOKUP(H8,$I$2:$I$16,$J$2:$J$16) -> 14 | H8: =_xlfn.XLOOKUP(A8,Data!A:A,Data!C:C) -> RTV | I8: Zabawki | J8: 10 | K8: CX | L8: 0.9 | M8: Rzadkie zamówienia, duże partie | P8: =_xlfn.XLOOKUP(A8,Data!A:A,Data!F:F) -> 810.15 | Q8: {=_xlfn.XLOOKUP(A8,'XYZ Analysis'!A:A,'XYZ Analysis'!$Z:Z)} -> 76.083333 | R8: =Q8/30 -> 2.5361111 | S8: =_xlfn.XLOOKUP(A8,'XYZ Analysis'!A:A,'XYZ Analysis'!AA:AA) -> 70.302274 | T8: =S8/30 -> 2.3434091 | U8: =ROUNDUP(_xlfn.NORM.S.INV(E8)*T8*SQRT(G8),0) -> 17 | V8: =R8*G8+U8 -> 52.505556 | W8: =SQRT(2*R8*365*$N$2/($N$2*P8)) -> 1.5116904
A9: SKU-0328 | B9: =_xlfn.XLOOKUP(A9, 'ABC Analysis'!A:A, 'ABC Analysis'!F:F) -> A | C9: =_xlfn.XLOOKUP(A9,'XYZ Analysis'!A:A,'XYZ Analysis'!AC:AC) -> X | D9: =B9&C9 -> AX | E9: =_xlfn.XLOOKUP(D9,K:K,L:L) -> 0.99 | F9: =_xlfn.XLOOKUP(D9,K:K,M:M) -> Niski zapas bezpieczeństwa, częste zamówienia małymi partiami | G9: =_xlfn.XLOOKUP(H9,$I$2:$I$16,$J$2:$J$16) -> 9 | H9: =_xlfn.XLOOKUP(A9,Data!A:A,Data!C:C) -> Motoryzacja | I9: Artykuły biurowe | J9: 5 | K9: CY | L9: 0.87 | M9: Podstawowy zapas bezpieczeństwa, przegląd sezonowy | P9: =_xlfn.XLOOKUP(A9,Data!A:A,Data!F:F) -> 171.72 | Q9: {=_xlfn.XLOOKUP(A9,'XYZ Analysis'!A:A,'XYZ Analysis'!$Z:Z)} -> 285.95833 | R9: =Q9/30 -> 9.5319444 | S9: =_xlfn.XLOOKUP(A9,'XYZ Analysis'!A:A,'XYZ Analysis'!AA:AA) -> 121.34987 | T9: =S9/30 -> 4.0449955 | U9: =ROUNDUP(_xlfn.NORM.S.INV(E9)*T9*SQRT(G9),0) -> 29 | V9: =R9*G9+U9 -> 114.7875 | W9: =SQRT(2*R9*365*$N$2/($N$2*P9)) -> 6.3656351
A10: SKU-0036 | B10: =_xlfn.XLOOKUP(A10, 'ABC Analysis'!A:A, 'ABC Analysis'!F:F) -> A | C10: =_xlfn.XLOOKUP(A10,'XYZ Analysis'!A:A,'XYZ Analysis'!AC:AC) -> Y | D10: =B10&C10 -> AY | E10: =_xlfn.XLOOKUP(D10,K:K,L:L) -> 0.97 | F10: =_xlfn.XLOOKUP(D10,K:K,M:M) -> Umiarkowany zapas bezpieczeństwa, zamówienia dostosowane do sezonowości | G10: =_xlfn.XLOOKUP(H10,$I$2:$I$16,$J$2:$J$16) -> 21 | H10: =_xlfn.XLOOKUP(A10,Data!A:A,Data!C:C) -> Meble | I10: Sport i rekreacja | J10: 8 | K10: CZ | L10: 0.85 | M10: Zamawianie na żądanie (make-to-order) zamiast trzymania zapasu | P10: =_xlfn.XLOOKUP(A10,Data!A:A,Data!F:F) -> 893.93 | Q10: {=_xlfn.XLOOKUP(A10,'XYZ Analysis'!A:A,'XYZ Analysis'!$Z:Z)} -> 53.875 | R10: =Q10/30 -> 1.7958333 | S10: =_xlfn.XLOOKUP(A10,'XYZ Analysis'!A:A,'XYZ Analysis'!AA:AA) -> 43.29291 | T10: =S10/30 -> 1.443097 | U10: =ROUNDUP(_xlfn.NORM.S.INV(E10)*T10*SQRT(G10),0) -> 13 | V10: =R10*G10+U10 -> 50.7125 | W10: =SQRT(2*R10*365*$N$2/($N$2*P10)) -> 1.2109959
A11: SKU-0214 | B11: =_xlfn.XLOOKUP(A11, 'ABC Analysis'!A:A, 'ABC Analysis'!F:F) -> A | C11: =_xlfn.XLOOKUP(A11,'XYZ Analysis'!A:A,'XYZ Analysis'!AC:AC) -> Z | D11: =B11&C11 -> AZ | E11: =_xlfn.XLOOKUP(D11,K:K,L:L) -> 0.95 | F11: =_xlfn.XLOOKUP(D11,K:K,M:M) -> Wysoki zapas bezpieczeństwa mimo wysokiego kosztu | G11: =_xlfn.XLOOKUP(H11,$I$2:$I$16,$J$2:$J$16) -> 14 | H11: =_xlfn.XLOOKUP(A11,Data!A:A,Data!C:C) -> RTV | I11: Ogród | J11: 12 | P11: =_xlfn.XLOOKUP(A11,Data!A:A,Data!F:F) -> 1958.3 | Q11: {=_xlfn.XLOOKUP(A11,'XYZ Analysis'!A:A,'XYZ Analysis'!$Z:Z)} -> 23 | R11: =Q11/30 -> 0.76666667 | S11: =_xlfn.XLOOKUP(A11,'XYZ Analysis'!A:A,'XYZ Analysis'!AA:AA) -> 28.748913 | T11: =S11/30 -> 0.9582971 | U11: =ROUNDUP(_xlfn.NORM.S.INV(E11)*T11*SQRT(G11),0) -> 6 | V11: =R11*G11+U11 -> 16.733333 | W11: =SQRT(2*R11*365*$N$2/($N$2*P11)) -> 0.53459527
A12: SKU-0396 | B12: =_xlfn.XLOOKUP(A12, 'ABC Analysis'!A:A, 'ABC Analysis'!F:F) -> A | C12: =_xlfn.XLOOKUP(A12,'XYZ Analysis'!A:A,'XYZ Analysis'!AC:AC) -> X | D12: =B12&C12 -> AX | E12: =_xlfn.XLOOKUP(D12,K:K,L:L) -> 0.99 | F12: =_xlfn.XLOOKUP(D12,K:K,M:M) -> Niski zapas bezpieczeństwa, częste zamówienia małymi partiami | G12: =_xlfn.XLOOKUP(H12,$I$2:$I$16,$J$2:$J$16) -> 12 | H12: =_xlfn.XLOOKUP(A12,Data!A:A,Data!C:C) -> AGD | I12: Motoryzacja | J12: 9 | P12: =_xlfn.XLOOKUP(A12,Data!A:A,Data!F:F) -> 501.15 | Q12: {=_xlfn.XLOOKUP(A12,'XYZ Analysis'!A:A,'XYZ Analysis'!$Z:Z)} -> 84.625 | R12: =Q12/30 -> 2.8208333 | S12: =_xlfn.XLOOKUP(A12,'XYZ Analysis'!A:A,'XYZ Analysis'!AA:AA) -> 13.056967 | T12: =S12/30 -> 0.43523222 | U12: =ROUNDUP(_xlfn.NORM.S.INV(E12)*T12*SQRT(G12),0) -> 4 | V12: =R12*G12+U12 -> 37.85 | W12: =SQRT(2*R12*365*$N$2/($N$2*P12)) -> 2.0270585
A13: SKU-0149 | B13: =_xlfn.XLOOKUP(A13, 'ABC Analysis'!A:A, 'ABC Analysis'!F:F) -> A | C13: =_xlfn.XLOOKUP(A13,'XYZ Analysis'!A:A,'XYZ Analysis'!AC:AC) -> X | D13: =B13&C13 -> AX | E13: =_xlfn.XLOOKUP(D13,K:K,L:L) -> 0.99 | F13: =_xlfn.XLOOKUP(D13,K:K,M:M) -> Niski zapas bezpieczeństwa, częste zamówienia małymi partiami | G13: =_xlfn.XLOOKUP(H13,$I$2:$I$16,$J$2:$J$16) -> 11 | H13: =_xlfn.XLOOKUP(A13,Data!A:A,Data!C:C) -> Narzędzia | I13: Spożywcze | J13: 4 | P13: =_xlfn.XLOOKUP(A13,Data!A:A,Data!F:F) -> 207.13 | Q13: {=_xlfn.XLOOKUP(A13,'XYZ Analysis'!A:A,'XYZ Analysis'!$Z:Z)} -> 175.45833 | R13: =Q13/30 -> 5.8486111 | S13: =_xlfn.XLOOKUP(A13,'XYZ Analysis'!A:A,'XYZ Analysis'!AA:AA) -> 19.540512 | T13: =S13/30 -> 0.65135039 | U13: =ROUNDUP(_xlfn.NORM.S.INV(E13)*T13*SQRT(G13),0) -> 6 | V13: =R13*G13+U13 -> 70.334722 | W13: =SQRT(2*R13*365*$N$2/($N$2*P13)) -> 4.5401092
A14: SKU-0070 | B14: =_xlfn.XLOOKUP(A14, 'ABC Analysis'!A:A, 'ABC Analysis'!F:F) -> A | C14: =_xlfn.XLOOKUP(A14,'XYZ Analysis'!A:A,'XYZ Analysis'!AC:AC) -> X | D14: =B14&C14 -> AX | E14: =_xlfn.XLOOKUP(D14,K:K,L:L) -> 0.99 | F14: =_xlfn.XLOOKUP(D14,K:K,M:M) -> Niski zapas bezpieczeństwa, częste zamówienia małymi partiami | G14: =_xlfn.XLOOKUP(H14,$I$2:$I$16,$J$2:$J$16) -> 10 | H14: =_xlfn.XLOOKUP(A14,Data!A:A,Data!C:C) -> Elektronika | I14: Meble | J14: 21 | P14: =_xlfn.XLOOKUP(A14,Data!A:A,Data!F:F) -> 320.53 | Q14: {=_xlfn.XLOOKUP(A14,'XYZ Analysis'!A:A,'XYZ Analysis'!$Z:Z)} -> 103.54167 | R14: =Q14/30 -> 3.4513889 | S14: =_xlfn.XLOOKUP(A14,'XYZ Analysis'!A:A,'XYZ Analysis'!AA:AA) -> 42.82326 | T14: =S14/30 -> 1.427442 | U14: =ROUNDUP(_xlfn.NORM.S.INV(E14)*T14*SQRT(G14),0) -> 11 | V14: =R14*G14+U14 -> 45.513889 | W14: =SQRT(2*R14*365*$N$2/($N$2*P14)) -> 2.8036515
A15: SKU-0092 | B15: =_xlfn.XLOOKUP(A15, 'ABC Analysis'!A:A, 'ABC Analysis'!F:F) -> A | C15: =_xlfn.XLOOKUP(A15,'XYZ Analysis'!A:A,'XYZ Analysis'!AC:AC) -> Y | D15: =B15&C15 -> AY | E15: =_xlfn.XLOOKUP(D15,K:K,L:L) -> 0.97 | F15: =_xlfn.XLOOKUP(D15,K:K,M:M) -> Umiarkowany zapas bezpieczeństwa, zamówienia dostosowane do sezonowości | G15: =_xlfn.XLOOKUP(H15,$I$2:$I$16,$J$2:$J$16) -> 12 | H15: =_xlfn.XLOOKUP(A15,Data!A:A,Data!C:C) -> Ogród | I15: Oświetlenie | J15: 8 | P15: =_xlfn.XLOOKUP(A15,Data!A:A,Data!F:F) -> 477.26 | Q15: {=_xlfn.XLOOKUP(A15,'XYZ Analysis'!A:A,'XYZ Analysis'!$Z:Z)} -> 68.833333 | R15: =Q15/30 -> 2.2944444 | S15: =_xlfn.XLOOKUP(A15,'XYZ Analysis'!A:A,'XYZ Analysis'!AA:AA) -> 40.420361 | T15: =S15/30 -> 1.3473454 | U15: =ROUNDUP(_xlfn.NORM.S.INV(E15)*T15*SQRT(G15),0) -> 9 | V15: =R15*G15+U15 -> 36.533333 | W15: =SQRT(2*R15*365*$N$2/($N$2*P15)) -> 1.8733662
A16: SKU-0068 | B16: =_xlfn.XLOOKUP(A16, 'ABC Analysis'!A:A, 'ABC Analysis'!F:F) -> A | C16: =_xlfn.XLOOKUP(A16,'XYZ Analysis'!A:A,'XYZ Analysis'!AC:AC) -> Z | D16: =B16&C16 -> AZ | E16: =_xlfn.XLOOKUP(D16,K:K,L:L) -> 0.95 | F16: =_xlfn.XLOOKUP(D16,K:K,M:M) -> Wysoki zapas bezpieczeństwa mimo wysokiego kosztu | G16: =_xlfn.XLOOKUP(H16,$I$2:$I$16,$J$2:$J$16) -> 21 | H16: =_xlfn.XLOOKUP(A16,Data!A:A,Data!C:C) -> Meble | I16: Narzędzia | J16: 11 | P16: =_xlfn.XLOOKUP(A16,Data!A:A,Data!F:F) -> 886.96 | Q16: {=_xlfn.XLOOKUP(A16,'XYZ Analysis'!A:A,'XYZ Analysis'!$Z:Z)} -> 31.166667 | R16: =Q16/30 -> 1.0388889 | S16: =_xlfn.XLOOKUP(A16,'XYZ Analysis'!A:A,'XYZ Analysis'!AA:AA) -> 36.107094 | T16: =S16/30 -> 1.2035698 | U16: =ROUNDUP(_xlfn.NORM.S.INV(E16)*T16*SQRT(G16),0) -> 10 | V16: =R16*G16+U16 -> 31.816667 | W16: =SQRT(2*R16*365*$N$2/($N$2*P16)) -> 0.92468532
A17: SKU-0450 | B17: =_xlfn.XLOOKUP(A17, 'ABC Analysis'!A:A, 'ABC Analysis'!F:F) -> A | C17: =_xlfn.XLOOKUP(A17,'XYZ Analysis'!A:A,'XYZ Analysis'!AC:AC) -> X | D17: =B17&C17 -> AX | E17: =_xlfn.XLOOKUP(D17,K:K,L:L) -> 0.99 | F17: =_xlfn.XLOOKUP(D17,K:K,M:M) -> Niski zapas bezpieczeństwa, częste zamówienia małymi partiami | G17: =_xlfn.XLOOKUP(H17,$I$2:$I$16,$J$2:$J$16) -> 21 | H17: =_xlfn.XLOOKUP(A17,Data!A:A,Data!C:C) -> Meble | P17: =_xlfn.XLOOKUP(A17,Data!A:A,Data!F:F) -> 329.19 | Q17: {=_xlfn.XLOOKUP(A17,'XYZ Analysis'!A:A,'XYZ Analysis'!$Z:Z)} -> 82.75 | R17: =Q17/30 -> 2.7583333 | S17: =_xlfn.XLOOKUP(A17,'XYZ Analysis'!A:A,'XYZ Analysis'!AA:AA) -> 40.394152 | T17: =S17/30 -> 1.3464717 | U17: =ROUNDUP(_xlfn.NORM.S.INV(E17)*T17*SQRT(G17),0) -> 15 | V17: =R17*G17+U17 -> 72.925 | W17: =SQRT(2*R17*365*$N$2/($N$2*P17)) -> 2.4732128
A18: SKU-0106 | B18: =_xlfn.XLOOKUP(A18, 'ABC Analysis'!A:A, 'ABC Analysis'!F:F) -> A | C18: =_xlfn.XLOOKUP(A18,'XYZ Analysis'!A:A,'XYZ Analysis'!AC:AC) -> Y | D18: =B18&C18 -> AY | E18: =_xlfn.XLOOKUP(D18,K:K,L:L) -> 0.97 | F18: =_xlfn.XLOOKUP(D18,K:K,M:M) -> Umiarkowany zapas bezpieczeństwa, zamówienia dostosowane do sezonowości | G18: =_xlfn.XLOOKUP(H18,$I$2:$I$16,$J$2:$J$16) -> 11 | H18: =_xlfn.XLOOKUP(A18,Data!A:A,Data!C:C) -> Narzędzia | P18: =_xlfn.XLOOKUP(A18,Data!A:A,Data!F:F) -> 427.6 | Q18: {=_xlfn.XLOOKUP(A18,'XYZ Analysis'!A:A,'XYZ Analysis'!$Z:Z)} -> 67.333333 | R18: =Q18/30 -> 2.2444444 | S18: =_xlfn.XLOOKUP(A18,'XYZ Analysis'!A:A,'XYZ Analysis'!AA:AA) -> 47.89021 | T18: =S18/30 -> 1.5963403 | U18: =ROUNDUP(_xlfn.NORM.S.INV(E18)*T18*SQRT(G18),0) -> 10 | V18: =R18*G18+U18 -> 34.688889 | W18: =SQRT(2*R18*365*$N$2/($N$2*P18)) -> 1.9574786
A19: SKU-0251 | B19: =_xlfn.XLOOKUP(A19, 'ABC Analysis'!A:A, 'ABC Analysis'!F:F) -> A | C19: =_xlfn.XLOOKUP(A19,'XYZ Analysis'!A:A,'XYZ Analysis'!AC:AC) -> X | D19: =B19&C19 -> AX | E19: =_xlfn.XLOOKUP(D19,K:K,L:L) -> 0.99 | F19: =_xlfn.XLOOKUP(D19,K:K,M:M) -> Niski zapas bezpieczeństwa, częste zamówienia małymi partiami | G19: =_xlfn.XLOOKUP(H19,$I$2:$I$16,$J$2:$J$16) -> 8 | H19: =_xlfn.XLOOKUP(A19,Data!A:A,Data!C:C) -> Oświetlenie | P19: =_xlfn.XLOOKUP(A19,Data!A:A,Data!F:F) -> 257.06 | Q19: {=_xlfn.XLOOKUP(A19,'XYZ Analysis'!A:A,'XYZ Analysis'!$Z:Z)} -> 105.45833 | R19: =Q19/30 -> 3.5152778 | S19: =_xlfn.XLOOKUP(A19,'XYZ Analysis'!A:A,'XYZ Analysis'!AA:AA) -> 15.402865 | T19: =S19/30 -> 0.51342885 | U19: =ROUNDUP(_xlfn.NORM.S.INV(E19)*T19*SQRT(G19),0) -> 4 | V19: =R19*G19+U19 -> 32.122222 | W19: =SQRT(2*R19*365*$N$2/($N$2*P19)) -> 3.1595411
A20: SKU-0385 | B20: =_xlfn.XLOOKUP(A20, 'ABC Analysis'!A:A, 'ABC Analysis'!F:F) -> A | C20: =_xlfn.XLOOKUP(A20,'XYZ Analysis'!A:A,'XYZ Analysis'!AC:AC) -> X | D20: =B20&C20 -> AX | E20: =_xlfn.XLOOKUP(D20,K:K,L:L) -> 0.99 | F20: =_xlfn.XLOOKUP(D20,K:K,M:M) -> Niski zapas bezpieczeństwa, częste zamówienia małymi partiami | G20: =_xlfn.XLOOKUP(H20,$I$2:$I$16,$J$2:$J$16) -> 12 | H20: =_xlfn.XLOOKUP(A20,Data!A:A,Data!C:C) -> Ogród | P20: =_xlfn.XLOOKUP(A20,Data!A:A,Data!F:F) -> 230.17 | Q20: {=_xlfn.XLOOKUP(A20,'XYZ Analysis'!A:A,'XYZ Analysis'!$Z:Z)} -> 112 | R20: =Q20/30 -> 3.7333333 | S20: =_xlfn.XLOOKUP(A20,'XYZ Analysis'!A:A,'XYZ Analysis'!AA:AA) -> 8.7749644 | T20: =S20/30 -> 0.29249881 | U20: =ROUNDUP(_xlfn.NORM.S.INV(E20)*T20*SQRT(G20),0) -> 3 | V20: =R20*G20+U20 -> 47.8 | W20: =SQRT(2*R20*365*$N$2/($N$2*P20)) -> 3.4410062
A21: SKU-0302 | B21: =_xlfn.XLOOKUP(A21, 'ABC Analysis'!A:A, 'ABC Analysis'!F:F) -> A | C21: =_xlfn.XLOOKUP(A21,'XYZ Analysis'!A:A,'XYZ Analysis'!AC:AC) -> X | D21: =B21&C21 -> AX | E21: =_xlfn.XLOOKUP(D21,K:K,L:L) -> 0.99 | F21: =_xlfn.XLOOKUP(D21,K:K,M:M) -> Niski zapas bezpieczeństwa, częste zamówienia małymi partiami | G21: =_xlfn.XLOOKUP(H21,$I$2:$I$16,$J$2:$J$16) -> 14 | H21: =_xlfn.XLOOKUP(A21,Data!A:A,Data!C:C) -> RTV | P21: =_xlfn.XLOOKUP(A21,Data!A:A,Data!F:F) -> 1005.72 | Q21: {=_xlfn.XLOOKUP(A21,'XYZ Analysis'!A:A,'XYZ Analysis'!$Z:Z)} -> 25.041667 | R21: =Q21/30 -> 0.83472222 | S21: =_xlfn.XLOOKUP(A21,'XYZ Analysis'!A:A,'XYZ Analysis'!AA:AA) -> 3.4336468 | T21: =S21/30 -> 0.11445489 | U21: =ROUNDUP(_xlfn.NORM.S.INV(E21)*T21*SQRT(G21),0) -> 1 | V21: =R21*G21+U21 -> 12.686111 | W21: =SQRT(2*R21*365*$N$2/($N$2*P21)) -> 0.77838395
A22: SKU-0035 | B22: =_xlfn.XLOOKUP(A22, 'ABC Analysis'!A:A, 'ABC Analysis'!F:F) -> A | C22: =_xlfn.XLOOKUP(A22,'XYZ Analysis'!A:A,'XYZ Analysis'!AC:AC) -> X | D22: =B22&C22 -> AX | E22: =_xlfn.XLOOKUP(D22,K:K,L:L) -> 0.99 | F22: =_xlfn.XLOOKUP(D22,K:K,M:M) -> Niski zapas bezpieczeństwa, częste zamówienia małymi partiami | G22: =_xlfn.XLOOKUP(H22,$I$2:$I$16,$J$2:$J$16) -> 21 | H22: =_xlfn.XLOOKUP(A22,Data!A:A,Data!C:C) -> Meble | P22: =_xlfn.XLOOKUP(A22,Data!A:A,Data!F:F) -> 723.46 | Q22: {=_xlfn.XLOOKUP(A22,'XYZ Analysis'!A:A,'XYZ Analysis'!$Z:Z)} -> 35 | R22: =Q22/30 -> 1.1666667 | S22: =_xlfn.XLOOKUP(A22,'XYZ Analysis'!A:A,'XYZ Analysis'!AA:AA) -> 4.0517486 | T22: =S22/30 -> 0.13505829 | U22: =ROUNDUP(_xlfn.NORM.S.INV(E22)*T22*SQRT(G22),0) -> 2 | V22: =R22*G22+U22 -> 26.5 | W22: =SQRT(2*R22*365*$N$2/($N$2*P22)) -> 1.0849946
A23: SKU-0237 | B23: =_xlfn.XLOOKUP(A23, 'ABC Analysis'!A:A, 'ABC Analysis'!F:F) -> A | C23: =_xlfn.XLOOKUP(A23,'XYZ Analysis'!A:A,'XYZ Analysis'!AC:AC) -> X | D23: =B23&C23 -> AX | E23: =_xlfn.XLOOKUP(D23,K:K,L:L) -> 0.99 | F23: =_xlfn.XLOOKUP(D23,K:K,M:M) -> Niski zapas bezpieczeństwa, częste zamówienia małymi partiami | G23: =_xlfn.XLOOKUP(H23,$I$2:$I$16,$J$2:$J$16) -> 12 | H23: =_xlfn.XLOOKUP(A23,Data!A:A,Data!C:C) -> AGD | P23: =_xlfn.XLOOKUP(A23,Data!A:A,Data!F:F) -> 464.85 | Q23: {=_xlfn.XLOOKUP(A23,'XYZ Analysis'!A:A,'XYZ Analysis'!$Z:Z)} -> 48.75 | R23: =Q23/30 -> 1.625 | S23: =_xlfn.XLOOKUP(A23,'XYZ Analysis'!A:A,'XYZ Analysis'!AA:AA) -> 4.145781 | T23: =S23/30 -> 0.1381927 | U23: =ROUNDUP(_xlfn.NORM.S.INV(E23)*T23*SQRT(G23),0) -> 2 | V23: =R23*G23+U23 -> 21.5 | W23: =SQRT(2*R23*365*$N$2/($N$2*P23)) -> 1.5974663
A24: SKU-0218 | B24: =_xlfn.XLOOKUP(A24, 'ABC Analysis'!A:A, 'ABC Analysis'!F:F) -> A | C24: =_xlfn.XLOOKUP(A24,'XYZ Analysis'!A:A,'XYZ Analysis'!AC:AC) -> Y | D24: =B24&C24 -> AY | E24: =_xlfn.XLOOKUP(D24,K:K,L:L) -> 0.97 | F24: =_xlfn.XLOOKUP(D24,K:K,M:M) -> Umiarkowany zapas bezpieczeństwa, zamówienia dostosowane do sezonowości | G24: =_xlfn.XLOOKUP(H24,$I$2:$I$16,$J$2:$J$16) -> 8 | H24: =_xlfn.XLOOKUP(A24,Data!A:A,Data!C:C) -> Sport i rekreacja | P24: =_xlfn.XLOOKUP(A24,Data!A:A,Data!F:F) -> 291.39 | Q24: {=_xlfn.XLOOKUP(A24,'XYZ Analysis'!A:A,'XYZ Analysis'!$Z:Z)} -> 78.541667 | R24: =Q24/30 -> 2.6180556 | S24: =_xlfn.XLOOKUP(A24,'XYZ Analysis'!A:A,'XYZ Analysis'!AA:AA) -> 75.757826 | T24: =S24/30 -> 2.5252609 | U24: =ROUNDUP(_xlfn.NORM.S.INV(E24)*T24*SQRT(G24),0) -> 14 | V24: =R24*G24+U24 -> 34.944444 | W24: =SQRT(2*R24*365*$N$2/($N$2*P24)) -> 2.5610233
A25: SKU-0045 | B25: =_xlfn.XLOOKUP(A25, 'ABC Analysis'!A:A, 'ABC Analysis'!F:F) -> A | C25: =_xlfn.XLOOKUP(A25,'XYZ Analysis'!A:A,'XYZ Analysis'!AC:AC) -> Y | D25: =B25&C25 -> AY | E25: =_xlfn.XLOOKUP(D25,K:K,L:L) -> 0.97 | F25: =_xlfn.XLOOKUP(D25,K:K,M:M) -> Umiarkowany zapas bezpieczeństwa, zamówienia dostosowane do sezonowości | G25: =_xlfn.XLOOKUP(H25,$I$2:$I$16,$J$2:$J$16) -> 12 | H25: =_xlfn.XLOOKUP(A25,Data!A:A,Data!C:C) -> Ogród | P25: =_xlfn.XLOOKUP(A25,Data!A:A,Data!F:F) -> 311.32 | Q25: {=_xlfn.XLOOKUP(A25,'XYZ Analysis'!A:A,'XYZ Analysis'!$Z:Z)} -> 73.25 | R25: =Q25/30 -> 2.4416667 | S25: =_xlfn.XLOOKUP(A25,'XYZ Analysis'!A:A,'XYZ Analysis'!AA:AA) -> 52.718 | T25: =S25/30 -> 1.7572667 | U25: =ROUNDUP(_xlfn.NORM.S.INV(E25)*T25*SQRT(G25),0) -> 12 | V25: =R25*G25+U25 -> 41.3 | W25: =SQRT(2*R25*365*$N$2/($N$2*P25)) -> 2.3927708
A26: SKU-0380 | B26: =_xlfn.XLOOKUP(A26, 'ABC Analysis'!A:A, 'ABC Analysis'!F:F) -> A | C26: =_xlfn.XLOOKUP(A26,'XYZ Analysis'!A:A,'XYZ Analysis'!AC:AC) -> Y | D26: =B26&C26 -> AY | E26: =_xlfn.XLOOKUP(D26,K:K,L:L) -> 0.97 | F26: =_xlfn.XLOOKUP(D26,K:K,M:M) -> Umiarkowany zapas bezpieczeństwa, zamówienia dostosowane do sezonowości | G26: =_xlfn.XLOOKUP(H26,$I$2:$I$16,$J$2:$J$16) -> 21 | H26: =_xlfn.XLOOKUP(A26,Data!A:A,Data!C:C) -> Meble | P26: =_xlfn.XLOOKUP(A26,Data!A:A,Data!F:F) -> 389.19 | Q26: {=_xlfn.XLOOKUP(A26,'XYZ Analysis'!A:A,'XYZ Analysis'!$Z:Z)} -> 55.791667 | R26: =Q26/30 -> 1.8597222 | S26: =_xlfn.XLOOKUP(A26,'XYZ Analysis'!A:A,'XYZ Analysis'!AA:AA) -> 38.828661 | T26: =S26/30 -> 1.2942887 | U26: =ROUNDUP(_xlfn.NORM.S.INV(E26)*T26*SQRT(G26),0) -> 12 | V26: =R26*G26+U26 -> 51.054167 | W26: =SQRT(2*R26*365*$N$2/($N$2*P26)) -> 1.8676893
A27: SKU-0059 | B27: =_xlfn.XLOOKUP(A27, 'ABC Analysis'!A:A, 'ABC Analysis'!F:F) -> A | C27: =_xlfn.XLOOKUP(A27,'XYZ Analysis'!A:A,'XYZ Analysis'!AC:AC) -> Y | D27: =B27&C27 -> AY | E27: =_xlfn.XLOOKUP(D27,K:K,L:L) -> 0.97 | F27: =_xlfn.XLOOKUP(D27,K:K,M:M) -> Umiarkowany zapas bezpieczeństwa, zamówienia dostosowane do sezonowości | G27: =_xlfn.XLOOKUP(H27,$I$2:$I$16,$J$2:$J$16) -> 14 | H27: =_xlfn.XLOOKUP(A27,Data!A:A,Data!C:C) -> RTV | P27: =_xlfn.XLOOKUP(A27,Data!A:A,Data!F:F) -> 962.59 | Q27: {=_xlfn.XLOOKUP(A27,'XYZ Analysis'!A:A,'XYZ Analysis'!$Z:Z)} -> 21.291667 | R27: =Q27/30 -> 0.70972222 | S27: =_xlfn.XLOOKUP(A27,'XYZ Analysis'!A:A,'XYZ Analysis'!AA:AA) -> 15.205479 | T27: =S27/30 -> 0.50684931 | U27: =ROUNDUP(_xlfn.NORM.S.INV(E27)*T27*SQRT(G27),0) -> 4 | V27: =R27*G27+U27 -> 13.936111 | W27: =SQRT(2*R27*365*$N$2/($N$2*P27)) -> 0.73364331
A28: SKU-0226 | B28: =_xlfn.XLOOKUP(A28, 'ABC Analysis'!A:A, 'ABC Analysis'!F:F) -> A | C28: =_xlfn.XLOOKUP(A28,'XYZ Analysis'!A:A,'XYZ Analysis'!AC:AC) -> X | D28: =B28&C28 -> AX | E28: =_xlfn.XLOOKUP(D28,K:K,L:L) -> 0.99 | F28: =_xlfn.XLOOKUP(D28,K:K,M:M) -> Niski zapas bezpieczeństwa, częste zamówienia małymi partiami | G28: =_xlfn.XLOOKUP(H28,$I$2:$I$16,$J$2:$J$16) -> 12 | H28: =_xlfn.XLOOKUP(A28,Data!A:A,Data!C:C) -> AGD | P28: =_xlfn.XLOOKUP(A28,Data!A:A,Data!F:F) -> 504.21 | Q28: {=_xlfn.XLOOKUP(A28,'XYZ Analysis'!A:A,'XYZ Analysis'!$Z:Z)} -> 39.791667 | R28: =Q28/30 -> 1.3263889 | S28: =_xlfn.XLOOKUP(A28,'XYZ Analysis'!A:A,'XYZ Analysis'!AA:AA) -> 4.3682488 | T28: =S28/30 -> 0.14560829 | U28: =ROUNDUP(_xlfn.NORM.S.INV(E28)*T28*SQRT(G28),0) -> 2 | V28: =R28*G28+U28 -> 17.916667 | W28: =SQRT(2*R28*365*$N$2/($N$2*P28)) -> 1.38577
... A31: SKU-0402 | B31: =_xlfn.XLOOKUP(A31, 'ABC Analysis'!A:A, 'ABC Analysis'!F:F) -> A | C31: =_xlfn.XLOOKUP(A31,'XYZ Analysis'!A:A,'XYZ Analysis'!AC:AC) -> Y | D31: =B31&C31 -> AY | E31: =_xlfn.XLOOKUP(D31,K:K,L:L) -> 0.97 | F31: =_xlfn.XLOOKUP(D31,K:K,M:M) -> Umiarkowany zapas bezpieczeństwa, zamówienia dostosowane do sezonowości | G31: =_xlfn.XLOOKUP(H31,$I$2:$I$16,$J$2:$J$16) -> 21 | H31: =_xlfn.XLOOKUP(A31,Data!A:A,Data!C:C) -> Meble | P31: =_xlfn.XLOOKUP(A31,Data!A:A,Data!F:F) -> 640.71 | Q31: {=_xlfn.XLOOKUP(A31,'XYZ Analysis'!A:A,'XYZ Analysis'!$Z:Z)} -> 31.041667 | R31: =Q31/30 -> 1.0347222 | S31: =_xlfn.XLOOKUP(A31,'XYZ Analysis'!A:A,'XYZ Analysis'!AA:AA) -> 21.302346 | T31: =S31/30 -> 0.71007819 | U31: =ROUNDUP(_xlfn.NORM.S.INV(E31)*T31*SQRT(G31),0) -> 7 | V31: =R31*G31+U31 -> 28.729167 | W31: =SQRT(2*R31*365*$N$2/($N$2*P31)) -> 1.0857818
A32: SKU-0310 | B32: =_xlfn.XLOOKUP(A32, 'ABC Analysis'!A:A, 'ABC Analysis'!F:F) -> A | C32: =_xlfn.XLOOKUP(A32,'XYZ Analysis'!A:A,'XYZ Analysis'!AC:AC) -> X | D32: =B32&C32 -> AX | E32: =_xlfn.XLOOKUP(D32,K:K,L:L) -> 0.99 | F32: =_xlfn.XLOOKUP(D32,K:K,M:M) -> Niski zapas bezpieczeństwa, częste zamówienia małymi partiami | G32: =_xlfn.XLOOKUP(H32,$I$2:$I$16,$J$2:$J$16) -> 7 | H32: =_xlfn.XLOOKUP(A32,Data!A:A,Data!C:C) -> Odzież | K32: Macierz ABC/XYZ liczba SKU | P32: =_xlfn.XLOOKUP(A32,Data!A:A,Data!F:F) -> 172.31 | Q32: {=_xlfn.XLOOKUP(A32,'XYZ Analysis'!A:A,'XYZ Analysis'!$Z:Z)} -> 108.41667 | R32: =Q32/30 -> 3.6138889 | S32: =_xlfn.XLOOKUP(A32,'XYZ Analysis'!A:A,'XYZ Analysis'!AA:AA) -> 48.297616 | T32: =S32/30 -> 1.6099205 | U32: =ROUNDUP(_xlfn.NORM.S.INV(E32)*T32*SQRT(G32),0) -> 10 | V32: =R32*G32+U32 -> 35.297222 | W32: =SQRT(2*R32*365*$N$2/($N$2*P32)) -> 3.9128535
A33: SKU-0303 | B33: =_xlfn.XLOOKUP(A33, 'ABC Analysis'!A:A, 'ABC Analysis'!F:F) -> A | C33: =_xlfn.XLOOKUP(A33,'XYZ Analysis'!A:A,'XYZ Analysis'!AC:AC) -> X | D33: =B33&C33 -> AX | E33: =_xlfn.XLOOKUP(D33,K:K,L:L) -> 0.99 | F33: =_xlfn.XLOOKUP(D33,K:K,M:M) -> Niski zapas bezpieczeństwa, częste zamówienia małymi partiami | G33: =_xlfn.XLOOKUP(H33,$I$2:$I$16,$J$2:$J$16) -> 14 | H33: =_xlfn.XLOOKUP(A33,Data!A:A,Data!C:C) -> RTV | J33: Wartość sprzedaży (ABC)> | K33: A | L33: B | M33: C | P33: =_xlfn.XLOOKUP(A33,Data!A:A,Data!F:F) -> 322.32 | Q33: {=_xlfn.XLOOKUP(A33,'XYZ Analysis'!A:A,'XYZ Analysis'!$Z:Z)} -> 53.666667 | R33: =Q33/30 -> 1.7888889 | S33: =_xlfn.XLOOKUP(A33,'XYZ Analysis'!A:A,'XYZ Analysis'!AA:AA) -> 6.624869 | T33: =S33/30 -> 0.22082897 | U33: =ROUNDUP(_xlfn.NORM.S.INV(E33)*T33*SQRT(G33),0) -> 2 | V33: =R33*G33+U33 -> 27.044444 | W33: =SQRT(2*R33*365*$N$2/($N$2*P33)) -> 2.0128411
A34: SKU-0169 | B34: =_xlfn.XLOOKUP(A34, 'ABC Analysis'!A:A, 'ABC Analysis'!F:F) -> A | C34: =_xlfn.XLOOKUP(A34,'XYZ Analysis'!A:A,'XYZ Analysis'!AC:AC) -> Y | D34: =B34&C34 -> AY | E34: =_xlfn.XLOOKUP(D34,K:K,L:L) -> 0.97 | F34: =_xlfn.XLOOKUP(D34,K:K,M:M) -> Umiarkowany zapas bezpieczeństwa, zamówienia dostosowane do sezonowości | G34: =_xlfn.XLOOKUP(H34,$I$2:$I$16,$J$2:$J$16) -> 9 | H34: =_xlfn.XLOOKUP(A34,Data!A:A,Data!C:C) -> Obuwie | J34: X | K34: =COUNTIF($D$2:$D$501,K$33&$J34) -> 44 | L34: =COUNTIF($D$2:$D$501,L$33&$J34) -> 57 | M34: =COUNTIF($D$2:$D$501,M$33&$J34) -> 99 | P34: =_xlfn.XLOOKUP(A34,Data!A:A,Data!F:F) -> 357.36 | Q34: {=_xlfn.XLOOKUP(A34,'XYZ Analysis'!A:A,'XYZ Analysis'!$Z:Z)} -> 49.458333 | R34: =Q34/30 -> 1.6486111 | S34: =_xlfn.XLOOKUP(A34,'XYZ Analysis'!A:A,'XYZ Analysis'!AA:AA) -> 29.077453 | T34: =S34/30 -> 0.96924843 | U34: =ROUNDUP(_xlfn.NORM.S.INV(E34)*T34*SQRT(G34),0) -> 6 | V34: =R34*G34+U34 -> 20.8375 | W34: =SQRT(2*R34*365*$N$2/($N$2*P34)) -> 1.8351331
A35: SKU-0195 | B35: =_xlfn.XLOOKUP(A35, 'ABC Analysis'!A:A, 'ABC Analysis'!F:F) -> A | C35: =_xlfn.XLOOKUP(A35,'XYZ Analysis'!A:A,'XYZ Analysis'!AC:AC) -> X | D35: =B35&C35 -> AX | E35: =_xlfn.XLOOKUP(D35,K:K,L:L) -> 0.99 | F35: =_xlfn.XLOOKUP(D35,K:K,M:M) -> Niski zapas bezpieczeństwa, częste zamówienia małymi partiami | G35: =_xlfn.XLOOKUP(H35,$I$2:$I$16,$J$2:$J$16) -> 12 | H35: =_xlfn.XLOOKUP(A35,Data!A:A,Data!C:C) -> Ogród | I35: Zmienność popytu (XYZ)> | J35: Y | K35: =COUNTIF($D$2:$D$501,K$33&$J35) -> 47 | L35: =COUNTIF($D$2:$D$501,L$33&$J35) -> 45 | M35: =COUNTIF($D$2:$D$501,M$33&$J35) -> 117 | P35: =_xlfn.XLOOKUP(A35,Data!A:A,Data!F:F) -> 406.99 | Q35: {=_xlfn.XLOOKUP(A35,'XYZ Analysis'!A:A,'XYZ Analysis'!$Z:Z)} -> 40.375 | R35: =Q35/30 -> 1.3458333 | S35: =_xlfn.XLOOKUP(A35,'XYZ Analysis'!A:A,'XYZ Analysis'!AA:AA) -> 3.5450964 | T35: =S35/30 -> 0.11816988 | U35: =ROUNDUP(_xlfn.NORM.S.INV(E35)*T35*SQRT(G35),0) -> 1 | V35: =R35*G35+U35 -> 17.15 | W35: =SQRT(2*R35*365*$N$2/($N$2*P35)) -> 1.553693
A36: SKU-0458 | B36: =_xlfn.XLOOKUP(A36, 'ABC Analysis'!A:A, 'ABC Analysis'!F:F) -> A | C36: =_xlfn.XLOOKUP(A36,'XYZ Analysis'!A:A,'XYZ Analysis'!AC:AC) -> Z | D36: =B36&C36 -> AZ | E36: =_xlfn.XLOOKUP(D36,K:K,L:L) -> 0.95 | F36: =_xlfn.XLOOKUP(D36,K:K,M:M) -> Wysoki zapas bezpieczeństwa mimo wysokiego kosztu | G36: =_xlfn.XLOOKUP(H36,$I$2:$I$16,$J$2:$J$16) -> 8 | H36: =_xlfn.XLOOKUP(A36,Data!A:A,Data!C:C) -> Sport i rekreacja | J36: Z | K36: =COUNTIF($D$2:$D$501,K$33&$J36) -> 11 | L36: =COUNTIF($D$2:$D$501,L$33&$J36) -> 19 | M36: =COUNTIF($D$2:$D$501,M$33&$J36) -> 61 | P36: =_xlfn.XLOOKUP(A36,Data!A:A,Data!F:F) -> 185.4 | Q36: {=_xlfn.XLOOKUP(A36,'XYZ Analysis'!A:A,'XYZ Analysis'!$Z:Z)} -> 87.708333 | R36: =Q36/30 -> 2.9236111 | S36: =_xlfn.XLOOKUP(A36,'XYZ Analysis'!A:A,'XYZ Analysis'!AA:AA) -> 92.675725 | T36: =S36/30 -> 3.0891908 | U36: =ROUNDUP(_xlfn.NORM.S.INV(E36)*T36*SQRT(G36),0) -> 15 | V36: =R36*G36+U36 -> 38.388889 | W36: =SQRT(2*R36*365*$N$2/($N$2*P36)) -> 3.3928633
A37: SKU-0343 | B37: =_xlfn.XLOOKUP(A37, 'ABC Analysis'!A:A, 'ABC Analysis'!F:F) -> A | C37: =_xlfn.XLOOKUP(A37,'XYZ Analysis'!A:A,'XYZ Analysis'!AC:AC) -> Y | D37: =B37&C37 -> AY | E37: =_xlfn.XLOOKUP(D37,K:K,L:L) -> 0.97 | F37: =_xlfn.XLOOKUP(D37,K:K,M:M) -> Umiarkowany zapas bezpieczeństwa, zamówienia dostosowane do sezonowości | G37: =_xlfn.XLOOKUP(H37,$I$2:$I$16,$J$2:$J$16) -> 7 | H37: =_xlfn.XLOOKUP(A37,Data!A:A,Data!C:C) -> Odzież | P37: =_xlfn.XLOOKUP(A37,Data!A:A,Data!F:F) -> 168.73 | Q37: {=_xlfn.XLOOKUP(A37,'XYZ Analysis'!A:A,'XYZ Analysis'!$Z:Z)} -> 99.833333 | R37: =Q37/30 -> 3.3277778 | S37: =_xlfn.XLOOKUP(A37,'XYZ Analysis'!A:A,'XYZ Analysis'!AA:AA) -> 61.149861 | T37: =S37/30 -> 2.0383287 | U37: =ROUNDUP(_xlfn.NORM.S.INV(E37)*T37*SQRT(G37),0) -> 11 | V37: =R37*G37+U37 -> 34.294444 | W37: =SQRT(2*R37*365*$N$2/($N$2*P37)) -> 3.7943941
A38: SKU-0029 | B38: =_xlfn.XLOOKUP(A38, 'ABC Analysis'!A:A, 'ABC Analysis'!F:F) -> A | C38: =_xlfn.XLOOKUP(A38,'XYZ Analysis'!A:A,'XYZ Analysis'!AC:AC) -> X | D38: =B38&C38 -> AX | E38: =_xlfn.XLOOKUP(D38,K:K,L:L) -> 0.99 | F38: =_xlfn.XLOOKUP(D38,K:K,M:M) -> Niski zapas bezpieczeństwa, częste zamówienia małymi partiami | G38: =_xlfn.XLOOKUP(H38,$I$2:$I$16,$J$2:$J$16) -> 21 | H38: =_xlfn.XLOOKUP(A38,Data!A:A,Data!C:C) -> Meble | P38: =_xlfn.XLOOKUP(A38,Data!A:A,Data!F:F) -> 639.1 | Q38: {=_xlfn.XLOOKUP(A38,'XYZ Analysis'!A:A,'XYZ Analysis'!$Z:Z)} -> 25 | R38: =Q38/30 -> 0.83333333 | S38: =_xlfn.XLOOKUP(A38,'XYZ Analysis'!A:A,'XYZ Analysis'!AA:AA) -> 4.7169906 | T38: =S38/30 -> 0.15723302 | U38: =ROUNDUP(_xlfn.NORM.S.INV(E38)*T38*SQRT(G38),0) -> 2 | V38: =R38*G38+U38 -> 19.5 | W38: =SQRT(2*R38*365*$N$2/($N$2*P38)) -> 0.97563281
A39: SKU-0309 | B39: =_xlfn.XLOOKUP(A39, 'ABC Analysis'!A:A, 'ABC Analysis'!F:F) -> A | C39: =_xlfn.XLOOKUP(A39,'XYZ Analysis'!A:A,'XYZ Analysis'!AC:AC) -> Y | D39: =B39&C39 -> AY | E39: =_xlfn.XLOOKUP(D39,K:K,L:L) -> 0.97 | F39: =_xlfn.XLOOKUP(D39,K:K,M:M) -> Umiarkowany zapas bezpieczeństwa, zamówienia dostosowane do sezonowości | G39: =_xlfn.XLOOKUP(H39,$I$2:$I$16,$J$2:$J$16) -> 9 | H39: =_xlfn.XLOOKUP(A39,Data!A:A,Data!C:C) -> Motoryzacja | P39: =_xlfn.XLOOKUP(A39,Data!A:A,Data!F:F) -> 142.94 | Q39: {=_xlfn.XLOOKUP(A39,'XYZ Analysis'!A:A,'XYZ Analysis'!$Z:Z)} -> 109.16667 | R39: =Q39/30 -> 3.6388889 | S39: =_xlfn.XLOOKUP(A39,'XYZ Analysis'!A:A,'XYZ Analysis'!AA:AA) -> 73.258485 | T39: =S39/30 -> 2.4419495 | U39: =ROUNDUP(_xlfn.NORM.S.INV(E39)*T39*SQRT(G39),0) -> 14 | V39: =R39*G39+U39 -> 46.75 | W39: =SQRT(2*R39*365*$N$2/($N$2*P39)) -> 4.3109098
A40: SKU-0432 | B40: =_xlfn.XLOOKUP(A40, 'ABC Analysis'!A:A, 'ABC Analysis'!F:F) -> A | C40: =_xlfn.XLOOKUP(A40,'XYZ Analysis'!A:A,'XYZ Analysis'!AC:AC) -> X | D40: =B40&C40 -> AX | E40: =_xlfn.XLOOKUP(D40,K:K,L:L) -> 0.99 | F40: =_xlfn.XLOOKUP(D40,K:K,M:M) -> Niski zapas bezpieczeństwa, częste zamówienia małymi partiami | G40: =_xlfn.XLOOKUP(H40,$I$2:$I$16,$J$2:$J$16) -> 21 | H40: =_xlfn.XLOOKUP(A40,Data!A:A,Data!C:C) -> Meble | P40: =_xlfn.XLOOKUP(A40,Data!A:A,Data!F:F) -> 1171.52 | Q40: {=_xlfn.XLOOKUP(A40,'XYZ Analysis'!A:A,'XYZ Analysis'!$Z:Z)} -> 13.75 | R40: =Q40/30 -> 0.45833333 | S40: =_xlfn.XLOOKUP(A40,'XYZ Analysis'!A:A,'XYZ Analysis'!AA:AA) -> 1.0507934 | T40: =S40/30 -> 0.035026445 | U40: =ROUNDUP(_xlfn.NORM.S.INV(E40)*T40*SQRT(G40),0) -> 1 | V40: =R40*G40+U40 -> 10.625 | W40: =SQRT(2*R40*365*$N$2/($N$2*P40)) -> 0.53441335
A41: SKU-0129 | B41: =_xlfn.XLOOKUP(A41, 'ABC Analysis'!A:A, 'ABC Analysis'!F:F) -> A | C41: =_xlfn.XLOOKUP(A41,'XYZ Analysis'!A:A,'XYZ Analysis'!AC:AC) -> Z | D41: =B41&C41 -> AZ | E41: =_xlfn.XLOOKUP(D41,K:K,L:L) -> 0.95 | F41: =_xlfn.XLOOKUP(D41,K:K,M:M) -> Wysoki zapas bezpieczeństwa mimo wysokiego kosztu | G41: =_xlfn.XLOOKUP(H41,$I$2:$I$16,$J$2:$J$16) -> 9 | H41: =_xlfn.XLOOKUP(A41,Data!A:A,Data!C:C) -> Motoryzacja | P41: =_xlfn.XLOOKUP(A41,Data!A:A,Data!F:F) -> 235.32 | Q41: {=_xlfn.XLOOKUP(A41,'XYZ Analysis'!A:A,'XYZ Analysis'!$Z:Z)} -> 65.291667 | R41: =Q41/30 -> 2.1763889 | S41: =_xlfn.XLOOKUP(A41,'XYZ Analysis'!A:A,'XYZ Analysis'!AA:AA) -> 68.488733 | T41: =S41/30 -> 2.2829578 | U41: =ROUNDUP(_xlfn.NORM.S.INV(E41)*T41*SQRT(G41),0) -> 12 | V41: =R41*G41+U41 -> 31.5875 | W41: =SQRT(2*R41*365*$N$2/($N$2*P41)) -> 2.5983656
A42: SKU-0199 | B42: =_xlfn.XLOOKUP(A42, 'ABC Analysis'!A:A, 'ABC Analysis'!F:F) -> A | C42: =_xlfn.XLOOKUP(A42,'XYZ Analysis'!A:A,'XYZ Analysis'!AC:AC) -> Y | D42: =B42&C42 -> AY | E42: =_xlfn.XLOOKUP(D42,K:K,L:L) -> 0.97 | F42: =_xlfn.XLOOKUP(D42,K:K,M:M) -> Umiarkowany zapas bezpieczeństwa, zamówienia dostosowane do sezonowości | G42: =_xlfn.XLOOKUP(H42,$I$2:$I$16,$J$2:$J$16) -> 21 | H42: =_xlfn.XLOOKUP(A42,Data!A:A,Data!C:C) -> Meble | P42: =_xlfn.XLOOKUP(A42,Data!A:A,Data!F:F) -> 1084.81 | Q42: {=_xlfn.XLOOKUP(A42,'XYZ Analysis'!A:A,'XYZ Analysis'!$Z:Z)} -> 14.5 | R42: =Q42/30 -> 0.48333333 | S42: =_xlfn.XLOOKUP(A42,'XYZ Analysis'!A:A,'XYZ Analysis'!AA:AA) -> 14.442414 | T42: =S42/30 -> 0.48141381 | U42: =ROUNDUP(_xlfn.NORM.S.INV(E42)*T42*SQRT(G42),0) -> 5 | V42: =R42*G42+U42 -> 15.15 | W42: =SQRT(2*R42*365*$N$2/($N$2*P42)) -> 0.57030603
...
